<?xml version="1.0"?>
<sdf version="1.5">
<model name="stewart_platform">

  <link name="base_link">
    <inertial>
      
      <mass value="1.0"/>
      <inertia
        ixx="0.02" ixy="0.0" ixz="0.0"
        iyy="0.02" iyz="0.0"
        izz="0.02"/>
    </inertial>
    <collision>
      <geometry>
        <cylinder radius="0.2" length="0.1" />
      </geometry>
        </collision>
    <visual>
      <origin xyz="0 0 0" rpy="0 0 0"/>
      <geometry>
        <cylinder radius="0.18" length="0.1" />
      </geometry>
    </visual>
  </link>

  <link name="proximal_link_1">
    <inertial>
        <mass value="0.18" />
        <inertia ixx="0.0002835" ixy="0.0" ixz="0.0" iyy="0.0002835" iyz="0.0" izz="0.000324" />
    </inertial>
    
    <collision>
      <geometry>
        <box size="0.2 0.01 0.01" />
      </geometry>
    </collision>
    <visual>
      <origin rpy="0.0 0.0 -1.5707" xyz="0.0 0.1 0.0" />
      <geometry>
        <box size="0.2 0.01 0.01" />
      </geometry>
    </visual>
  </link>

  <link name="proximal_link_2">
    <inertial>
        <mass value="0.18" />
        <inertia ixx="0.0002835" ixy="0.0" ixz="0.0" iyy="0.0002835" iyz="0.0" izz="0.000324" />
    </inertial>
    
    <collision>
      <geometry>
        <box size="0.2 0.01 0.01" />
      </geometry>
    </collision>
    <visual>
      <origin rpy="0.0 0.0 -1.5707" xyz="0.0 0.1 0.0" />
      <geometry>
        <box size="0.2 0.01 0.01" />
      </geometry>
    </visual>
  </link>

  <link name="proximal_link_3">
    <inertial>
        <mass value="0.18" />
        <inertia ixx="0.0002835" ixy="0.0" ixz="0.0" iyy="0.0002835" iyz="0.0" izz="0.000324" />
    </inertial>
    
    <collision>
      <geometry>
        <box size="0.2 0.01 0.01" />
      </geometry>
    </collision>
    <visual>
      <origin rpy="0.0 0.0 1.5707" xyz="0.0 -0.1 0.0" />
      <geometry>
        <box size="0.2 0.01 0.01" />
      </geometry>
    </visual>
  </link>

  <link name="proximal_link_4">
    <inertial>
        <mass value="0.18" />
        <inertia ixx="0.0002835" ixy="0.0" ixz="0.0" iyy="0.0002835" iyz="0.0" izz="0.000324" />
    </inertial>
    
    <collision>
      <geometry>
        <box size="0.2 0.01 0.01" />
      </geometry>
    </collision>
    <visual>
      <origin rpy="0.0 0.0 1.5707" xyz="0.0 -0.1 0.0" />
      <geometry>
        <box size="0.2 0.01 0.01" />
      </geometry>
    </visual>
  </link>

  <link name="proximal_link_5">
    <inertial>
        <mass value="0.18" />
        <inertia ixx="0.0002835" ixy="0.0" ixz="0.0" iyy="0.0002835" iyz="0.0" izz="0.000324" />
    </inertial>
    
    <collision>
      <geometry>
        <box size="0.2 0.01 0.01" />
      </geometry>
    </collision>
    <visual>
      <origin rpy="0.0 3.14 0.0" xyz="-0.1 0.0 0.0" />
      <geometry>
        <box size="0.2 0.01 0.01" />
      </geometry>
    </visual>
  </link>

  <link name="proximal_link_6">
    <inertial>
        <mass value="0.18" />
        <inertia ixx="0.0002835" ixy="0.0" ixz="0.0" iyy="0.0002835" iyz="0.0" izz="0.000324" />
    </inertial>
    
    <collision>
      <geometry>
        <box size="0.2 0.01 0.01" />
      </geometry>
    </collision>
    <visual>
      <origin rpy="0.0 3.14 0.0" xyz="-0.1 0.0 0.0" />
      <geometry>
        <box size="0.2 0.01 0.01" />
      </geometry>
    </visual>
  </link>

  <joint name="base_to_proximal_link_1" type="continuous">
    <parent link="base_link"/>
    <child link="proximal_link_1"/>
    <axis xyz="1 0 0"/>
    <origin xyz="-0.05 0.2 0.1" rpy="0.0 0.0 0.0"/> 
  </joint>

  <joint name="base_to_proximal_link_2" type="continuous">
    <parent link="base_link"/>
    <child link="proximal_link_2"/>
    <axis xyz="1 0 0"/>
    <origin xyz="0.05 0.2 0.1" rpy="0.0 0.0 0.0"/> 
  </joint>

  <joint name="base_to_proximal_link_3" type="continuous">
    <parent link="base_link"/>
    <child link="proximal_link_3"/>
    <axis xyz="-1 0 0"/>
    <origin xyz="0.05 -0.2 0.1" rpy="0.0 0.0 0.0"/> 
  </joint>

  <joint name="base_to_proximal_link_4" type="continuous">
    <parent link="base_link"/>
    <child link="proximal_link_4"/>
    <axis xyz="-1 0 0"/>
    <origin xyz="-0.05 -0.2 0.1" rpy="0.0 0.0 0.0"/> 
  </joint>

  <joint name="base_to_proximal_link_5" type="continuous">
    <parent link="base_link"/>
    <child link="proximal_link_5"/>
    <axis xyz="0 1 0"/>
    <origin xyz="-0.2 -0.05 0.1" rpy="0.0 0.0 0.0"/> 
  </joint>

  <joint name="base_to_proximal_link_6" type="continuous">
    <parent link="base_link"/>
    <child link="proximal_link_6"/>
    <axis xyz="0 1 0"/>
    <origin xyz="-0.2 0.05 0.1" rpy="0.0 0.0 0.0"/> 
  </joint>

  <gazebo>
    <plugin name="gazebo_ros_control" filename="libgazebo_ros_control.so">
      <robotNamespace>/simple_model</robotNamespace>
    </plugin>
  </gazebo>

  <!-- transmission -->
  <transmission name="base_to_proximal_link_1">
    <type>transmission_interface/SimpleTransmission</type>
    <actuator name="motor1">
      <mechanicalReduction>1</mechanicalReduction>
    </actuator>
    <joint name="base_to_proximal_link_1">
      <hardwareInterface>EffortJointInterface</hardwareInterface>
    </joint>
  </transmission>

  <transmission name="base_to_proximal_link_2">
    <type>transmission_interface/SimpleTransmission</type>
    <actuator name="motor2">
      <mechanicalReduction>1</mechanicalReduction>
    </actuator>
    <joint name="base_to_proximal_link_2">
      <hardwareInterface>EffortJointInterface</hardwareInterface>
    </joint>
  </transmission>

  <transmission name="base_to_proximal_link_3">
    <type>transmission_interface/SimpleTransmission</type>
    <actuator name="motor3">
      <mechanicalReduction>1</mechanicalReduction>
    </actuator>
    <joint name="base_to_proximal_link_3">
      <hardwareInterface>EffortJointInterface</hardwareInterface>
    </joint>
  </transmission>

  <transmission name="base_to_proximal_link_4">
    <type>transmission_interface/SimpleTransmission</type>
    <actuator name="motor4">
      <mechanicalReduction>1</mechanicalReduction>
    </actuator>
    <joint name="base_to_proximal_link_4">
      <hardwareInterface>EffortJointInterface</hardwareInterface>
    </joint>
  </transmission>

  <transmission name="base_to_proximal_link_5">
    <type>transmission_interface/SimpleTransmission</type>
    <actuator name="motor5">
      <mechanicalReduction>1</mechanicalReduction>
    </actuator>
    <joint name="base_to_proximal_link_5">
      <hardwareInterface>EffortJointInterface</hardwareInterface>
    </joint>
  </transmission>

  <transmission name="base_to_proximal_link_6">
    <type>transmission_interface/SimpleTransmission</type>
    <actuator name="motor6">
      <mechanicalReduction>1</mechanicalReduction>
    </actuator>
    <joint name="base_to_proximal_link_6">
      <hardwareInterface>EffortJointInterface</hardwareInterface>
    </joint>
  </transmission>
</sdf>