<?xml version="1.0"?>
<sdf version="1.4">
<model name="stewart_platform">
	
  <plugin name="joint_controller" filename="libjoint_controller.so"/>

  <joint name="proximal_link_1_joint" type="revolute">
		<parent>base_link</parent>
		<child>proximal_link_1</child>
		<pose>-0.1 0 0 0 0 0</pose>
		<axis>
			<xyz>0.5000001943375613 -0.8660252915835662 0</xyz>
      <limit>
				<lower> -0.785398 </lower>
				<upper> 1.57079 </upper>
				<velocity> 1 </velocity>
			</limit>
		</axis>
	</joint>

  <joint name="proximal_link_2_joint" type="revolute">
		<parent>base_link</parent>
		<child>proximal_link_2</child>
		<pose>-0.1 0 0 0 0 0</pose>
		<axis>
			<xyz>0.5000001943375613 -0.8660252915835662 0</xyz>
      <limit>
				<lower> -0.785398 </lower>
				<upper> 1.57079 </upper>
				<velocity> 1 </velocity>
			</limit>
		</axis>
	</joint>

	<joint name="proximal_link_3_joint" type="revolute">
		<parent>base_link</parent>
		<child>proximal_link_3</child>
		<pose>-0.1 0 0 0 0 0</pose>
		<axis>
			<xyz>0.5000001943375613 0.8660252915835662 0</xyz>
      <limit>
				<lower> -0.785398 </lower>
				<upper> 1.57079 </upper>
				<velocity> 1 </velocity>
			</limit>
		</axis>
	</joint>

  <joint name="proximal_link_4_joint" type="revolute">
		<parent>base_link</parent>
		<child>proximal_link_4</child>
		<pose>-0.1 0 0 0 0 0</pose>
		<axis>
			<xyz>0.5000001943375613 0.8660252915835662 0</xyz>
      <limit>
				<lower> -0.785398 </lower>
				<upper> 1.57079 </upper>
				<velocity> 1 </velocity>
			</limit>
		</axis>
	</joint>

	<joint name="proximal_link_5_joint" type="revolute">
		<parent>base_link</parent>
		<child>proximal_link_5</child>
		<pose>-0.1 0 0 0 0 0</pose>
		<axis>
			<xyz>-1 0 0</xyz>
      <limit>
				<lower> -0.785398 </lower>
				<upper> 1.57079 </upper>
				<velocity> 1 </velocity>
			</limit>
		</axis>
	</joint>

  <joint name="proximal_link_6_joint" type="revolute">
		<parent>base_link</parent>
		<child>proximal_link_6</child>
		<pose>-0.1 0 0 0 0 0</pose>
		<axis>
			<xyz>-1 0 0</xyz>
      <limit>
				<lower> -0.785398 </lower>
				<upper> 1.57079 </upper>
				<velocity> 1 </velocity>
			</limit>
		</axis>
	</joint>

  <joint name="distal_link_1_joint" type="ball">
		<parent>proximal_link_1</parent>
		<child>distal_link_1</child>
		<pose> 0.2 0 0 0 0 0</pose>
		<axis>
			<xyz>1 0 0</xyz>
		</axis>
	</joint>

  <joint name="distal_link_2_joint" type="ball">
		<parent>proximal_link_2</parent>
		<child>distal_link_2</child>
		<pose> 0.2 0 0 0 0 0</pose>
		<axis>
			<xyz>1 0 0</xyz>
		</axis>
	</joint>

  <joint name="distal_link_3_joint" type="ball">
		<parent>proximal_link_3</parent>
		<child>distal_link_3</child>
		<pose> 0.2 0 0 0 0 0</pose>
		<axis>
			<xyz>1 0 0</xyz>
		</axis>
	</joint>

  <joint name="distal_link_4_joint" type="ball">
		<parent>proximal_link_4</parent>
		<child>distal_link_4</child>
		<pose> 0.2 0 0 0 0 0</pose>
		<axis>
			<xyz>1 0 0</xyz>
		</axis>
	</joint>

  <joint name="distal_link_5_joint" type="ball">
		<parent>proximal_link_5</parent>
		<child>distal_link_5</child>
		<pose> 0.2 0 0 0 0 0</pose>
		<axis>
			<xyz>1 0 0</xyz>
		</axis>
	</joint>

  <joint name="distal_link_6_joint" type="ball">
		<parent>proximal_link_6</parent>
		<child>distal_link_6</child>
		<pose> 0.2 0 0 0 0 0</pose>
		<axis>
			<xyz>1 0 0</xyz>
		</axis>
	</joint>

  <joint name="platform_link_1_joint" type="ball">
		<parent>distal_link_1</parent>
		<child>platform_link</child>
		<pose>0.09562178401447893 -0.025621756807220356 0 0 0 0</pose>
	</joint>

  <joint name="platform_link_2_joint" type="ball">
		<parent>distal_link_2</parent>
		<child>platform_link</child>
		<pose>0.025621756807220356 0.09562178401447893 0 0 0 0</pose>
	</joint>

  <joint name="platform_link_3_joint" type="ball">
		<parent>distal_link_3</parent>
		<child>platform_link</child>
		<pose>-0.025621756807220356 0.09562178401447893 0 0 0 0</pose>
	</joint>

  <joint name="platform_link_4_joint" type="ball">
		<parent>distal_link_4</parent>
		<child>platform_link</child>
		<pose>-0.09562178401447893 -0.025621756807220356 0 0 0 0</pose>
	</joint>

  <joint name="platform_link_5_joint" type="ball">
		<parent>distal_link_5</parent>
		<child>platform_link</child>
		<pose>-0.07 -0.07 0 0 0 0</pose>
	</joint>

  <joint name="platform_link_6_joint" type="ball">
		<parent>distal_link_6</parent>
		<child>platform_link</child>
		<pose>0.07 -0.07 0 0 0 0</pose>
	</joint>

  <link name="base_link">
    <pose>0 0 0.05 0 0 0</pose>
    <inertial>
    <mass>0.1</mass>
    <inertia>
      <ixx>0.0005625</ixx>
      <ixy>0.0</ixy>
      <ixz>0.0</ixz>
      <iyy>0.0005625</iyy> 
      <iyz>0.0</iyz>
      <izz>0.001125</izz>
    </inertia>
    </inertial>
    <collision name="collision">
      <geometry>
        <cylinder>
          <radius>0.15524174696260024</radius>
          <length>0.1</length>
        </cylinder> 
      </geometry>
    </collision>
    <visual name="visual">
      <geometry>
        <cylinder>
          <radius>0.15524174696260024</radius>
          <length>0.1</length>
        </cylinder> 
      </geometry>
    </visual>
  </link>

  <link name="proximal_link_1">
    <pose>0.23650633066939403 0.09035903692104766 0.1 0 0 0.523599</pose>
    <inertial>
      <mass>0.002</mass>
      <inertia>
        <ixx>1.0000000000000001e-07</ixx>
        <ixy>0.0</ixy>
        <ixz>0.0</ixz>
        <iyy>6.716398000000002e-05</iyy> 
        <iyz>0.0</iyz>
        <izz>6.716398000000002e-05</izz>
      </inertia>
    </inertial>
    <collision name="collision">
      <geometry>
        <box>
          <size>0.2 0.02 0.02</size>
        </box> 
      </geometry>
    </collision>
    <visual name="visual">
      <geometry>
        <box>
          <size>0.2 0.02 0.02</size>
        </box> 
      </geometry>
    </visual>
  </link>

  <link name="proximal_link_2">
    <pose>0.19650631512238914 0.15964106024773295 0.1 0 0 0.523599</pose>
    <inertial>
    <mass>0.002</mass>
    <inertia>
      <ixx>1.0000000000000001e-07</ixx>
      <ixy>0.0</ixy>
      <ixz>0.0</ixz>
      <iyy>6.716398000000002e-05</iyy> 
      <iyz>0.0</iyz>
      <izz>6.716398000000002e-05</izz>
    </inertia>
    </inertial>
    <collision name="collision">
      <geometry>
        <box>
          <size>0.2 0.02 0.02</size>
        </box> 
      </geometry>
    </collision>
    <visual name = "visual">
      <geometry>
        <box>
          <size>0.2 0.02 0.02</size>
        </box> 
      </geometry>
    </visual>
  </link>

  <link name="proximal_link_3">
    <pose>-0.19650631512238914 0.15964106024773295 0.1 0 0 2.61799</pose>
    <inertial>
    <mass>0.002</mass>
    <inertia>
      <ixx>1.0000000000000001e-07</ixx>
      <ixy>0.0</ixy>
      <ixz>0.0</ixz>
      <iyy>6.716398000000002e-05</iyy> 
      <iyz>0.0</iyz>
      <izz>6.716398000000002e-05</izz>
    </inertia>
    </inertial>
    <collision name="collision">
      <geometry>
        <box>
          <size>0.2 0.02 0.02</size>
        </box> 
      </geometry>
    </collision>
    <visual name = "visual">
      <geometry>
        <box>
          <size>0.2 0.02 0.02</size>
        </box> 
      </geometry>
    </visual>
  </link>

  <link name="proximal_link_4">
    <pose>-0.23650633066939403 0.09035903692104766 0.1 0 0 2.61799</pose>
    <inertial>
    <mass>0.002</mass>
    <inertia>
      <ixx>1.0000000000000001e-07</ixx>
      <ixy>0.0</ixy>
      <ixz>0.0</ixz>
      <iyy>6.716398000000002e-05</iyy> 
      <iyz>0.0</iyz>
      <izz>6.716398000000002e-05</izz>
    </inertia>
    </inertial>
    <collision name="collision">
      <geometry>
        <box>
          <size>0.2 0.02 0.02</size>
        </box> 
      </geometry>
    </collision>
    <visual name = "visual">
      <geometry>
        <box>
          <size>0.2 0.02 0.02</size>
        </box> 
      </geometry>
    </visual>
  </link>

  <link name="proximal_link_5">
    <pose>-0.04 -0.25 0.1 0 0 4.71239</pose>
    <inertial>
    <mass>0.002</mass>
    <inertia>
      <ixx>1.0000000000000001e-07</ixx>
      <ixy>0.0</ixy>
      <ixz>0.0</ixz>
      <iyy>6.716398000000002e-05</iyy> 
      <iyz>0.0</iyz>
      <izz>6.716398000000002e-05</izz>
    </inertia>
    </inertial>
    <collision name="collision">
      <geometry>
        <box>
          <size>0.2 0.02 0.02</size>
        </box> 
      </geometry>
    </collision>
    <visual name = "visual">
      <geometry>
        <box>
          <size>0.2 0.02 0.02</size>
        </box> 
      </geometry>
    </visual>
  </link>

  <link name="proximal_link_6">
    <pose>0.04 -0.25 0.1 0 0 4.71239</pose>
    <inertial>
    <mass>0.002</mass>
    <inertia>
      <ixx>1.0000000000000001e-07</ixx>
      <ixy>0.0</ixy>
      <ixz>0.0</ixz>
      <iyy>6.716398000000002e-05</iyy> 
      <iyz>0.0</iyz>
      <izz>6.716398000000002e-05</izz>
    </inertia>
    </inertial>
    <collision name="collision">
      <geometry>
        <box>
          <size>0.2 0.02 0.02</size>
        </box> 
      </geometry>
    </collision>
    <visual name = "visual">
      <geometry>
        <box>
          <size>0.2 0.02 0.02</size>
        </box> 
      </geometry>
    </visual>
  </link>

  <link name="distal_link_1">
    <pose>0.2093653219211148 0.05736864977379172 0.24203872711341792 -1.4655813026652293 0.7926265735749716 0.6303346726491357</pose>
    <inertial>
    <mass>0.001</mass>
    <inertia>
      <ixx>1.2500000000000001e-08</ixx>
      <ixy>0.0</ixy>
      <ixz>0.0</ixz>
      <iyy>0.0001333904975</iyy> 
      <iyz>0.0</iyz>
      <izz>0.0001333904975</izz>
    </inertia>
    </inertial>
    <collision name="collision">
      <geometry>
        <box>
          <size>0.4 0.01 0.01</size>
        </box> 
      </geometry>
    </collision>
    <visual name = "visual">
      <geometry>
        <box>
          <size>0.4 0.01 0.01</size>
        </box> 
      </geometry>
    </visual>
  </link>

  <link name="distal_link_2">
    <pose>0.15436530054398306 0.152631431847984 0.24203872711341792  -1.4655813026652293 0.7926265735749716 0.4168633273508644</pose>
    <inertial>
    <mass>0.001</mass>
    <inertia>
      <ixx>1.2500000000000001e-08</ixx>
      <ixy>0.0</ixy>
      <ixz>0.0</ixz>
      <iyy>0.0001333904975</iyy> 
      <iyz>0.0</iyz>
      <izz>0.0001333904975</izz>
    </inertia>
    </inertial>
    <collision name="collision">
      <geometry>
        <box>
          <size>0.4 0.01 0.01</size>
        </box> 
      </geometry>
    </collision>
    <visual name = "visual">
      <geometry>
        <box>
          <size>0.4 0.01 0.01</size>
        </box> 
      </geometry>
    </visual>
  </link>

  <link name="distal_link_3">
    <pose>-0.15436530054398306 0.152631431847984 0.24203872711341792  -1.4655813026652293 0.7926265735749716 2.7247256726491353</pose>
    <inertial>
    <mass>0.001</mass>
    <inertia>
      <ixx>1.2500000000000001e-08</ixx>
      <ixy>0.0</ixy>
      <ixz>0.0</ixz>
      <iyy>0.0001333904975</iyy> 
      <iyz>0.0</iyz>
      <izz>0.0001333904975</izz>
    </inertia>
    </inertial>
    <collision name="collision">
      <geometry>
        <box>
          <size>0.4 0.01 0.01</size>
        </box> 
      </geometry>
    </collision>
    <visual name = "visual">
      <geometry>
        <box>
          <size>0.4 0.01 0.01</size>
        </box> 
      </geometry>
    </visual>
  </link>

  <link name="distal_link_4">
    <pose>-0.2093653219211148 0.05736864977379172 0.24203872711341792  -1.4655813026652293 0.7926265735749716 2.5112543273508643</pose>
    <inertial>
    <mass>0.001</mass>
    <inertia>
      <ixx>1.2500000000000001e-08</ixx>
      <ixy>0.0</ixy>
      <ixz>0.0</ixz>
      <iyy>0.0001333904975</iyy> 
      <iyz>0.0</iyz>
      <izz>0.0001333904975</izz>
    </inertia>
    </inertial>
    <collision name="collision">
      <geometry>
        <box>
          <size>0.4 0.01 0.01</size>
        </box> 
      </geometry>
    </collision>
    <visual name = "visual">
      <geometry>
        <box>
          <size>0.4 0.01 0.01</size>
        </box> 
      </geometry>
    </visual>
  </link>

  <link name="distal_link_5">
    <pose>-0.05500000000000001 -0.21 0.24203872711341792  -1.4655813026652293 0.7926265735749716 4.819125672649136</pose>
    <inertial>
    <mass>0.001</mass>
    <inertia>
      <ixx>1.2500000000000001e-08</ixx>
      <ixy>0.0</ixy>
      <ixz>0.0</ixz>
      <iyy>0.0001333904975</iyy> 
      <iyz>0.0</iyz>
      <izz>0.0001333904975</izz>
    </inertia>
    </inertial>
    <collision name="collision">
      <geometry>
        <box>
          <size>0.4 0.01 0.01</size>
        </box> 
      </geometry>
    </collision>
    <visual name = "visual">
      <geometry>
        <box>
          <size>0.4 0.01 0.01</size>
        </box> 
      </geometry>
    </visual>
  </link>

  <link name="distal_link_6">
    <pose>0.05500000000000001 -0.21 0.24203872711341792  -1.4655813026652293 0.7926265735749716 4.605654327350864</pose>
    <inertial>
    <mass>0.001</mass>
    <inertia>
      <ixx>1.2500000000000001e-08</ixx>
      <ixy>0.0</ixy>
      <ixz>0.0</ixz>
      <iyy>0.0001333904975</iyy> 
      <iyz>0.0</iyz>
      <izz>0.0001333904975</izz>
    </inertia>
    </inertial>
    <collision name="collision">
      <geometry>
        <box>
          <size>0.4 0.01 0.01</size>
        </box> 
      </geometry>
    </collision>
    <visual name = "visual">
      <geometry>
        <box>
          <size>0.4 0.01 0.01</size>
        </box> 
      </geometry>
    </visual>
  </link>

  <link name="platform_link">
    <pose>0 0 0.3840774542268358 0 0 0</pose>
    <inertial>
    <mass>0.001</mass>
    <inertia>
      <ixx>0.0005625</ixx>
      <ixy>0.0</ixy>
      <ixz>0.0</ixz>
      <iyy>0.0005625</iyy> 
      <iyz>0.0</iyz>
      <izz>0.001125</izz>
    </inertia>
    </inertial>
    <collision name="collision">
      <geometry>
        <cylinder>
          <radius>0.09899494936611666</radius>
          <length>0.01</length>
        </cylinder>  
      </geometry>
    </collision>
    <visual name = "visual">
      <geometry>
        <cylinder>
          <radius>0.09899494936611666</radius>
          <length>0.01</length>
        </cylinder> 
      </geometry>
    </visual>
  </link>
</model>
</sdf>